<?xml version="1.0" ?>
<!-- =================================================================================== -->
<!-- |    This document was autogenerated by xacro from /home/ros/project/src/car_arm/urdf/car.urdf.xacro | -->
<!-- |    EDITING THIS FILE BY HAND IS NOT RECOMMENDED                                 | -->
<!-- =================================================================================== -->
<robot name="my_car">
    <material name="black">
        <color rgba="0.0 0.0 0.0 1.0" />
    </material>
    <material name="blue">
        <color rgba="0.0 0.0 0.8 1.0" />
    </material>
    <material name="green">
        <color rgba="0.0 0.8 0.0 1.0" />
    </material>
    <material name="grey">
        <color rgba="0.2 0.2 0.2 1.0" />
    </material>
    <material name="orange">
        <color rgba="1.0 0.4235294117647059 0.0392156862745098 1.0" />
    </material>
    <material name="brown">
        <color rgba="0.8705882352941177 0.8117647058823529 0.7647058823529411 1.0" />
    </material>
    <material name="red">
        <color rgba="0.8 0.0 0.0 1.0" />
    </material>
    <material name="white">
        <color rgba="1.0 1.0 1.0 1.0" />
    </material>
    <material name="yellow">
        <color rgba="1.0 1.0 0.0 1.0" />
    </material>
    <material name="purple">
        <color rgba="0.5 0.0 0.5 1.0" />
    </material>
    <material name="pink">
        <color rgba="1.0 0.75 0.8 1.0" />
    </material>
    <material name="cyan">
        <color rgba="0.0 1.0 1.0 1.0" />
    </material>
    <material name="magenta">
        <color rgba="1.0 0.0 1.0 1.0" />
    </material>
    <material name="light_blue">
        <color rgba="0.68 0.85 0.9 1.0" />
    </material>
    <material name="dark_green">
        <color rgba="0.0 0.39 0.0 1.0" />
    </material>
    <material name="olive">
        <color rgba="0.5 0.5 0.0 1.0" />
    </material>
    <material name="teal">
        <color rgba="0.0 0.5 0.5 1.0" />
    </material>
    <!-- 底盘 -->
    <link name="base_footprint">
        <visual>
            <geometry>
                <sphere radius="0.001" />
            </geometry>
        </visual>
    </link>
    <link name="base_link">
        <visual>
            <geometry>
                <box size="0.2 0.15 0.05" />
            </geometry>
            <origin rpy="0 0 0" xyz="0 0 0" />
            <material name="white">
                <color rgba="0.5 0.3 0.0 0.5" />
            </material>
        </visual>
        <collision>
            <geometry>
                <box size="0.2 0.15 0.05" />
                <origin rpy="0 0 0" xyz="0 0 0" />
            </geometry>
        </collision>
        <inertial>
            <mass value="1.5" />
            <inertia ixx="0.0031250000000000006" ixy="0" ixz="0" iyy="0.005312500000000001" iyz="0" izz="0.0078125" />
            <origin xyz="0 0 0" rpy="0 0 0" />
        </inertial>
    </link>
    <joint name="base_link2base_footprint" type="fixed">
        <parent link="base_footprint" />
        <child link="base_link" />
        <origin xyz="0 0 0.041" />
    </joint>
    <gazebo reference="base_link">
        <material>Gazebo/Blue</material>
        <plugin name="gazebo_ros_control">
            <robotNamespace>/</robotNamespace>
        </plugin>
    </gazebo>
    <link name="left_wheel">
        <visual>
            <geometry>
                <cylinder length="0.035" radius="0.03" />
            </geometry>
            <origin rpy="1.570795 0.0 0.0" xyz="0.0 0.0 0.0" />
            <material name="black" />
        </visual>
        <collision>
            <geometry>
                <cylinder length="0.035" radius="0.03" />
            </geometry>
            <origin rpy="1.570795 0.0 0.0" xyz="0.0 0.0 0.0" />
        </collision>
        <inertial>
            <mass value="0.1" />
            <inertia ixx="3.270833333333333e-05" ixy="0" ixz="0" iyy="3.270833333333333e-05" iyz="0" izz="4.4999999999999996e-05" />
            <origin xyz="0 0 0" rpy="0 0 0" />
        </inertial>
    </link>
    <joint name="left_wheel2base_link" type="continuous">
        <parent link="base_link" />
        <child link="left_wheel" />
        <origin xyz="0 0.075 -0.011000000000000003" />
        <axis xyz="0 1 0" />
    </joint>
    <gazebo reference="left_wheel">
        <material>Gazebo/Black</material>
    </gazebo>
    <link name="right_wheel">
        <visual>
            <geometry>
                <cylinder length="0.035" radius="0.03" />
            </geometry>
            <origin rpy="1.570795 0.0 0.0" xyz="0.0 0.0 0.0" />
            <material name="black" />
        </visual>
        <collision>
            <geometry>
                <cylinder length="0.035" radius="0.03" />
            </geometry>
            <origin rpy="1.570795 0.0 0.0" xyz="0.0 0.0 0.0" />
        </collision>
        <inertial>
            <mass value="0.1" />
            <inertia ixx="3.270833333333333e-05" ixy="0" ixz="0" iyy="3.270833333333333e-05" iyz="0" izz="4.4999999999999996e-05" />
            <origin xyz="0 0 0" rpy="0 0 0" />
        </inertial>
    </link>
    <joint name="right_wheel2base_link" type="continuous">
        <parent link="base_link" />
        <child link="right_wheel" />
        <origin xyz="0 -0.075 -0.011000000000000003" />
        <axis xyz="0 1 0" />
    </joint>
    <gazebo reference="right_wheel">
        <material>Gazebo/Black</material>
    </gazebo>
    <link name="front_wheel_1">
        <visual>
            <geometry>
                <sphere radius="0.008" />
            </geometry>
            <origin rpy="0 0 0" xyz="0 0 0" />
            <material name="black" />
        </visual>
        <collision>
            <geometry>
                <sphere radius="0.008" />
            </geometry>
            <origin rpy="0 0 0" xyz="0 0 0" />
        </collision>
        <inertial>
            <mass value="0.03" />
            <inertia ixx="7.680000000000001e-07" ixy="0" ixz="0" iyy="7.680000000000001e-07" iyz="0" izz="7.680000000000001e-07" />
            <origin xyz="0 0 0" rpy="0 0 0" />
        </inertial>
    </link>
    <joint name="front_wheel2base_link_1" type="continuous">
        <parent link="base_link" />
        <child link="front_wheel_1" />
        <origin xyz="0.07 0.05 -0.033" />
        <axis xyz="1 1 1" />
    </joint>
    <gazebo reference="front_wheel_1">
        <material>Gazebo/Black</material>
    </gazebo>
    <link name="front_wheel_2">
        <visual>
            <geometry>
                <sphere radius="0.008" />
            </geometry>
            <origin rpy="0 0 0" xyz="0 0 0" />
            <material name="black" />
        </visual>
        <collision>
            <geometry>
                <sphere radius="0.008" />
            </geometry>
            <origin rpy="0 0 0" xyz="0 0 0" />
        </collision>
        <inertial>
            <mass value="0.03" />
            <inertia ixx="7.680000000000001e-07" ixy="0" ixz="0" iyy="7.680000000000001e-07" iyz="0" izz="7.680000000000001e-07" />
            <origin xyz="0 0 0" rpy="0 0 0" />
        </inertial>
    </link>
    <joint name="front_wheel2base_link_2" type="continuous">
        <parent link="base_link" />
        <child link="front_wheel_2" />
        <origin xyz="0.07 -0.05 -0.033" />
        <axis xyz="1 1 1" />
    </joint>
    <gazebo reference="front_wheel_2">
        <material>Gazebo/Black</material>
    </gazebo>
    <link name="back_wheel_1">
        <visual>
            <geometry>
                <sphere radius="0.008" />
            </geometry>
            <origin rpy="0 0 0" xyz="0 0 0" />
            <material name="black" />
        </visual>
        <collision>
            <geometry>
                <sphere radius="0.008" />
            </geometry>
            <origin rpy="0 0 0" xyz="0 0 0" />
        </collision>
        <inertial>
            <mass value="0.03" />
            <inertia ixx="7.680000000000001e-07" ixy="0" ixz="0" iyy="7.680000000000001e-07" iyz="0" izz="7.680000000000001e-07" />
            <origin xyz="0 0 0" rpy="0 0 0" />
        </inertial>
    </link>
    <joint name="back_wheel2base_link_1" type="continuous">
        <parent link="base_link" />
        <child link="back_wheel_1" />
        <origin xyz="-0.07 0.05 -0.033" />
        <axis xyz="1 1 1" />
    </joint>
    <gazebo reference="back_wheel_1">
        <material>Gazebo/Black</material>
    </gazebo>
    <link name="back_wheel_2">
        <visual>
            <geometry>
                <sphere radius="0.008" />
            </geometry>
            <origin rpy="0 0 0" xyz="0 0 0" />
            <material name="black" />
        </visual>
        <collision>
            <geometry>
                <sphere radius="0.008" />
            </geometry>
            <origin rpy="0 0 0" xyz="0 0 0" />
        </collision>
        <inertial>
            <mass value="0.03" />
            <inertia ixx="7.680000000000001e-07" ixy="0" ixz="0" iyy="7.680000000000001e-07" iyz="0" izz="7.680000000000001e-07" />
            <origin xyz="0 0 0" rpy="0 0 0" />
        </inertial>
    </link>
    <joint name="back_wheel2base_link_2" type="continuous">
        <parent link="base_link" />
        <child link="back_wheel_2" />
        <origin xyz="-0.07 -0.05 -0.033" />
        <axis xyz="1 1 1" />
    </joint>
    <gazebo reference="back_wheel_2">
        <material>Gazebo/Black</material>
    </gazebo>
    <!-- 摄像头安装的z坐标:底盘高度 / 2 + 摄像头高度 / 2  -->
    <!-- 摄像头质量 -->
    <!-- 摄像头关节以及link -->
    <link name="camera">
        <visual>
            <geometry>
                <box size="0.01 0.025 0.025" />
            </geometry>
            <origin rpy="0.0 0.0 0.0" xyz="0.0 0.0 0.0" />
            <material name="black" />
        </visual>
        <collision>
            <geometry>
                <box size="0.01 0.025 0.025" />
            </geometry>
            <origin rpy="0.0 0.0 0.0" xyz="0.0 0.0 0.0" />
        </collision>
        <inertial>
            <mass value="0.01" />
            <inertia ixx="1.041666666666667e-06" ixy="0" ixz="0" iyy="6.041666666666668e-07" iyz="0" izz="6.041666666666668e-07" />
            <origin xyz="0 0 0" rpy="0 0 0" />
        </inertial>
    </link>
    <joint name="camera2base_link" type="fixed">
        <parent link="base_link" />
        <child link="camera" />
        <origin xyz="0.08 0.0 0.037500000000000006" />
    </joint>
    <gazebo reference="camera">
        <material>Gazebo/Blue</material>
    </gazebo>
    <!-- 支架安装的z坐标:底盘高度 / 2 + 支架高度 / 2  -->
    <!-- 支架质量 -->
    <link name="support">
        <visual>
            <geometry>
                <cylinder length="0.15" radius="0.01" />
            </geometry>
            <origin rpy="0.0 0.0 0.0" xyz="0.0 0.0 0.0" />
            <material name="red">
                <color rgba="0.8 0.2 0.0 0.8" />
            </material>
        </visual>
        <collision>
            <geometry>
                <cylinder length="0.15" radius="0.01" />
            </geometry>
            <origin rpy="0.0 0.0 0.0" xyz="0.0 0.0 0.0" />
        </collision>
        <inertial>
            <mass value="0.02" />
            <inertia ixx="3.8e-05" ixy="0" ixz="0" iyy="3.8e-05" iyz="0" izz="1.0000000000000002e-06" />
            <origin xyz="0 0 0" rpy="0 0 0" />
        </inertial>
    </link>
    <joint name="support2base_link" type="fixed">
        <parent link="base_link" />
        <child link="support" />
        <origin xyz="0.0 0.0 0.1" />
    </joint>
    <gazebo reference="support">
        <material>Gazebo/White</material>
    </gazebo>
    <!-- 雷达安装的z坐标:支架高度 / 2 + 雷达高度 / 2  -->
    <!-- 雷达质量 -->
    <!-- 雷达关节以及link -->
    <link name="laser">
        <visual>
            <geometry>
                <cylinder length="0.05" radius="0.03" />
            </geometry>
            <origin rpy="0.0 0.0 0.0" xyz="0.0 0.0 0.0" />
            <material name="black" />
        </visual>
        <collision>
            <geometry>
                <cylinder length="0.05" radius="0.03" />
            </geometry>
            <origin rpy="0.0 0.0 0.0" xyz="0.0 0.0 0.0" />
        </collision>
        <inertial>
            <mass value="0.1" />
            <inertia ixx="4.333333333333333e-05" ixy="0" ixz="0" iyy="4.333333333333333e-05" iyz="0" izz="4.4999999999999996e-05" />
            <origin xyz="0 0 0" rpy="0 0 0" />
        </inertial>
    </link>
    <joint name="laser2support" type="fixed">
        <parent link="support" />
        <child link="laser" />
        <origin xyz="0.0 0.0 0.1" />
    </joint>
    <gazebo reference="laser">
        <material>Gazebo/Black</material>
    </gazebo>
    <!-- Transmission is important to link the joints and the controller -->
    <transmission name="left_wheel2base_link_trans">
        <type>transmission_interface/SimpleTransmission</type>
        <joint name="left_wheel2base_link">
            <hardwareInterface>hardware_interface/VelocityJointInterface</hardwareInterface>
        </joint>
        <actuator name="left_wheel2base_link_motor">
            <hardwareInterface>hardware_interface/VelocityJointInterface</hardwareInterface>
            <mechanicalReduction>1</mechanicalReduction>
        </actuator>
    </transmission>
    <!-- Transmission is important to link the joints and the controller -->
    <transmission name="right_wheel2base_link_trans">
        <type>transmission_interface/SimpleTransmission</type>
        <joint name="right_wheel2base_link">
            <hardwareInterface>hardware_interface/VelocityJointInterface</hardwareInterface>
        </joint>
        <actuator name="right_wheel2base_link_motor">
            <hardwareInterface>hardware_interface/VelocityJointInterface</hardwareInterface>
            <mechanicalReduction>1</mechanicalReduction>
        </actuator>
    </transmission>
    <!-- 控制器 -->
    <gazebo>
        <plugin filename="libgazebo_ros_diff_drive.so" name="differential_drive_controller">
            <rosDebugLevel>Debug</rosDebugLevel>
            <publishWheelTF>true</publishWheelTF>
            <robotNamespace>/</robotNamespace>
            <publishTf>1</publishTf>
            <publishWheelJointState>true</publishWheelJointState>
            <alwaysOn>true</alwaysOn>
            <updateRate>100.0</updateRate>
            <legacyMode>true</legacyMode>
            <leftJoint>left_wheel2base_link</leftJoint>
            <!-- 左轮 -->
            <rightJoint>right_wheel2base_link</rightJoint>
            <!-- 右轮 -->
            <wheelSeparation>0.15</wheelSeparation>
            <!-- 车轮间距 -->
            <wheelDiameter>0.06</wheelDiameter>
            <!-- 车轮直径 -->
            <broadcastTF>1</broadcastTF>
            <publishWheelTF>false</publishWheelTF>
            <wheelTorque>30</wheelTorque>
            <wheelAcceleration>1.8</wheelAcceleration>
            <commandTopic>cmd_vel</commandTopic>
            <!-- 运动控制话题 -->
            <odometryFrame>odom</odometryFrame>
            <odometryTopic>odom</odometryTopic>
            <!-- 里程计话题 -->
            <robotBaseFrame>base_footprint</robotBaseFrame>
            <!-- 根坐标系 -->
        </plugin>
    </gazebo>
    <gazebo reference="camera">
        <sensor name="camera" type="depth">
            <always_on>true</always_on>
            <update_rate>20.0</update_rate>
            <camera>
                <horizontal_fov>1.0471966666666666</horizontal_fov>
                <image>
                    <format>R8G8B8</format>
                    <width>640</width>
                    <height>480</height>
                </image>
                <clip>
                    <near>0.05</near>
                    <far>8.0</far>
                </clip>
            </camera>
            <plugin filename="libgazebo_ros_openni_kinect.so" name="kinect_camera_controller">
                <cameraName>camera</cameraName>
                <alwaysOn>true</alwaysOn>
                <updateRate>10</updateRate>
                <imageTopicName>rgb/image_raw</imageTopicName>
                <depthImageTopicName>depth/image_raw</depthImageTopicName>
                <pointCloudTopicName>depth/points</pointCloudTopicName>
                <cameraInfoTopicName>rgb/camera_info</cameraInfoTopicName>
                <depthImageCameraInfoTopicName>depth/camera_info</depthImageCameraInfoTopicName>
                <frameName>camera</frameName>
                <baseline>0.1</baseline>
                <distortion_k1>0.0</distortion_k1>
                <distortion_k2>0.0</distortion_k2>
                <distortion_k3>0.0</distortion_k3>
                <distortion_t1>0.0</distortion_t1>
                <distortion_t2>0.0</distortion_t2>
                <pointCloudCutoff>0.4</pointCloudCutoff>
            </plugin>
        </sensor>
    </gazebo>
    <!-- 雷达 -->
    <gazebo reference="laser">
        <sensor name="rplidar" type="ray">
            <pose>0 0 0 0 0 0</pose>
            <visualize>true</visualize>
            <update_rate>5.5</update_rate>
            <ray>
                <scan>
                    <horizontal>
                        <samples>360</samples>
                        <resolution>1</resolution>
                        <min_angle>-3</min_angle>
                        <max_angle>3</max_angle>
                    </horizontal>
                </scan>
                <range>
                    <min>0.10</min>
                    <max>30.0</max>
                    <resolution>0.01</resolution>
                </range>
                <noise>
                    <type>gaussian</type>
                    <mean>0.0</mean>
                    <stddev>0.01</stddev>
                </noise>
            </ray>
            <plugin filename="libgazebo_ros_laser.so" name="gazebo_rplidar">
                <topicName>/scan</topicName>
                <frameName>laser</frameName>
            </plugin>
        </sensor>
    </gazebo>
    <!-- /////////////////////////////////////   LINK1  ////////////////////////////////////////////// -->
    <link name="link1">
        <visual>
            <origin rpy="0 0 0" xyz="0 0 0.025" />
            <geometry>
                <cylinder length="0.05" radius="0.015" />
            </geometry>
            <material name="white" />
        </visual>
        <collision>
            <origin rpy="0 0 0" xyz="0  0 0.025" />
            <geometry>
                <cylinder length="0.05" radius="0.015" />
            </geometry>
        </collision>
        <inertial>
            <mass value="0.5" />
            <inertia ixx="0.00013229166666666668" ixy="0" ixz="0" iyy="0.00013229166666666668" iyz="0" izz="5.625e-05" />
            <origin xyz="0 0 0" rpy="0 0 0" />
        </inertial>
    </link>
    <joint name="joint1" type="revolute">
        <parent link="base_link" />
        <child link="link1" />
        <origin rpy="0 0 0" xyz="0.05 0.03 0.035" />
        <axis xyz="0 0 1" />
        <limit effort="300" lower="-2.96" upper="2.96" velocity="1" />
    </joint>
    <link name="link2">
        <visual>
            <origin rpy="0 0 0" xyz="0 0 0.03" />
            <geometry>
                <cylinder length="0.06" radius="0.01" />
            </geometry>
            <material name="grey" />
        </visual>
        <collision>
            <origin rpy="0 0 0" xyz="0  0 0.03" />
            <geometry>
                <cylinder length="0.06" radius="0.01" />
            </geometry>
        </collision>
        <inertial>
            <mass value="0.05" />
            <inertia ixx="1.625e-05" ixy="0" ixz="0" iyy="1.625e-05" iyz="0" izz="2.5e-06" />
            <origin xyz="0 0 0" rpy="0 0 0" />
        </inertial>
    </link>
    <joint name="joint2" type="revolute">
        <parent link="link1" />
        <child link="link2" />
        <origin rpy="0 0 0" xyz="0 0 0.060000000000000005" />
        <axis xyz="0 1 0" />
        <limit effort="300" lower="-1.5707963" upper="1.5707963" velocity="1" />
    </joint>
    <link name="link3">
        <visual>
            <origin rpy="0 0 0" xyz="0 0 0.045" />
            <geometry>
                <cylinder length="0.09" radius="0.01" />
            </geometry>
            <material name="white" />
        </visual>
        <collision>
            <origin rpy="0 0 0" xyz="0  0 0.045" />
            <geometry>
                <cylinder length="0.09" radius="0.01" />
            </geometry>
        </collision>
        <inertial>
            <mass value="0.05" />
            <inertia ixx="3.5000000000000004e-05" ixy="0" ixz="0" iyy="3.5000000000000004e-05" iyz="0" izz="2.5e-06" />
            <origin xyz="0 0 0" rpy="0 0 0" />
        </inertial>
    </link>
    <joint name="joint3" type="revolute">
        <parent link="link2" />
        <child link="link3" />
        <origin rpy="0 0 0" xyz="0 0 0.06999999999999999" />
        <axis xyz="0 1 0" />
        <limit effort="300" lower="-1.5707963" upper="1.5707963" velocity="1" />
    </joint>
    <link name="link4">
        <visual>
            <origin rpy="0 0 0" xyz="0 0 0.015" />
            <geometry>
                <cylinder length="0.03" radius="0.01" />
            </geometry>
            <material name="grey" />
        </visual>
        <collision>
            <origin rpy="0 0 0" xyz="0  0 0.015" />
            <geometry>
                <cylinder length="0.03" radius="0.01" />
            </geometry>
        </collision>
        <inertial>
            <mass value="0.05" />
            <inertia ixx="4.9999999999999996e-06" ixy="0" ixz="0" iyy="4.9999999999999996e-06" iyz="0" izz="2.5e-06" />
            <origin xyz="0 0 0" rpy="0 0 0" />
        </inertial>
    </link>
    <joint name="joint4" type="revolute">
        <parent link="link3" />
        <child link="link4" />
        <origin rpy="0 0 0" xyz="0 0 0.09999999999999999" />
        <axis xyz="0 1 0" />
        <limit effort="300" lower="-1.5707963" upper="1.5707963" velocity="1" />
    </joint>
    <link name="link5">
        <visual>
            <origin rpy="0 0 0" xyz="0 0 0.0025" />
            <geometry>
                <cylinder length="0.005" radius="0.02" />
            </geometry>
            <material name="light_blue" />
        </visual>
        <collision>
            <origin rpy="0 0 0" xyz="0  0 0.0025" />
            <geometry>
                <cylinder length="0.005" radius="0.02" />
            </geometry>
        </collision>
        <inertial>
            <mass value="0.05" />
            <inertia ixx="5.104166666666667e-06" ixy="0" ixz="0" iyy="5.104166666666667e-06" iyz="0" izz="1e-05" />
            <origin xyz="0 0 0" rpy="0 0 0" />
        </inertial>
    </link>
    <joint name="joint5" type="revolute">
        <parent link="link4" />
        <child link="link5" />
        <origin rpy="0 0 0" xyz="0 0 0.03" />
        <axis xyz="0 0 1" />
        <limit effort="300" lower="-3.1415926" upper="3.1415926" velocity="1" />
    </joint>
    <link name="left_gripper">
        <visual>
            <origin rpy="0 1.5707963 0" xyz="0 0 0.015" />
            <geometry>
                <box size="0.03 0.005 0.002" />
            </geometry>
            <material name="grey" />
        </visual>
        <collision>
            <origin rpy="0 0 0" xyz="0 0 0.015" />
            <geometry>
                <box size="0.03 0.005 0.002" />
            </geometry>
        </collision>
        <inertial>
            <mass value="0.02" />
            <inertia ixx="4.8333333333333336e-08" ixy="0" ixz="0" iyy="1.5066666666666667e-06" iyz="0" izz="1.5416666666666666e-06" />
            <origin xyz="0 0 0" rpy="0 0 0" />
        </inertial>
    </link>
    <joint name="left_gripper_joint" type="fixed">
        <parent link="link5" />
        <child link="left_gripper" />
        <origin rpy="0 0 0" xyz="0 0.017 0.005" />
    </joint>
    <link name="right_gripper">
        <visual>
            <origin rpy="0 1.5707963 0" xyz="0 0 0.015" />
            <geometry>
                <box size="0.03 0.005 0.002" />
            </geometry>
            <material name="grey" />
        </visual>
        <collision>
            <origin rpy="0 0 0" xyz="0 0 0.015" />
            <geometry>
                <box size="0.03 0.005 0.002" />
            </geometry>
        </collision>
        <inertial>
            <mass value="0.02" />
            <inertia ixx="4.8333333333333336e-08" ixy="0" ixz="0" iyy="1.5066666666666667e-06" iyz="0" izz="1.5416666666666666e-06" />
            <origin xyz="0 0 0" rpy="0 0 0" />
        </inertial>
    </link>
    <joint name="right_gripper_joint" type="prismatic">
        <parent link="link5" />
        <child link="right_gripper" />
        <origin rpy="0 0 0" xyz="0 -0.017 0.005" />
        <axis xyz="0 1 0" />
        <limit effort="100" lower="0" upper="0.03" velocity="1.0" />
        <dynamics damping="50" friction="1" />
    </joint>
    <link name="grasping_frame" />
    <joint name="grasping_frame_joint" type="fixed">
        <parent link="link5" />
        <child link="grasping_frame" />
        <origin rpy="0 0 0" xyz="0 0 0.005" />
    </joint>
    <gazebo reference="link1">
        <material>Gazebo/Blue</material>
    </gazebo>
    <gazebo reference="link2">
        <material>Gazebo/White</material>
    </gazebo>
    <gazebo reference="link3">
        <material>Gazebo/Blue</material>
    </gazebo>
    <gazebo reference="link4">
        <material>Gazebo/Black</material>
    </gazebo>
    <gazebo reference="link5">
        <material>Gazebo/White</material>
    </gazebo>
    <gazebo reference="left_gripper">
        <material>Gazebo/White</material>
    </gazebo>
    <gazebo reference="right_gripper">
        <material>Gazebo/White</material>
    </gazebo>
    <transmission name="tran1">
        <type>transmission_interface/SimpleTransmission</type>
        <joint name="joint1">
            <hardwareInterface>hardware_interface/PositionJointInterface</hardwareInterface>
        </joint>
        <actuator name="motor1">
            <hardwareInterface>hardware_interface/PositionJointInterface</hardwareInterface>
            <mechanicalReduction>1</mechanicalReduction>
        </actuator>
    </transmission>
    <transmission name="tran2">
        <type>transmission_interface/SimpleTransmission</type>
        <joint name="joint2">
            <hardwareInterface>hardware_interface/PositionJointInterface</hardwareInterface>
        </joint>
        <actuator name="motor2">
            <hardwareInterface>hardware_interface/PositionJointInterface</hardwareInterface>
            <mechanicalReduction>1</mechanicalReduction>
        </actuator>
    </transmission>
    <transmission name="tran3">
        <type>transmission_interface/SimpleTransmission</type>
        <joint name="joint3">
            <hardwareInterface>hardware_interface/PositionJointInterface</hardwareInterface>
        </joint>
        <actuator name="motor3">
            <hardwareInterface>hardware_interface/PositionJointInterface</hardwareInterface>
            <mechanicalReduction>1</mechanicalReduction>
        </actuator>
    </transmission>
    <transmission name="tran4">
        <type>transmission_interface/SimpleTransmission</type>
        <joint name="joint4">
            <hardwareInterface>hardware_interface/PositionJointInterface</hardwareInterface>
        </joint>
        <actuator name="motor4">
            <hardwareInterface>hardware_interface/PositionJointInterface</hardwareInterface>
            <mechanicalReduction>1</mechanicalReduction>
        </actuator>
    </transmission>
    <transmission name="tran5">
        <type>transmission_interface/SimpleTransmission</type>
        <joint name="joint5">
            <hardwareInterface>hardware_interface/PositionJointInterface</hardwareInterface>
        </joint>
        <actuator name="motor5">
            <hardwareInterface>hardware_interface/PositionJointInterface</hardwareInterface>
            <mechanicalReduction>1</mechanicalReduction>
        </actuator>
    </transmission>
    <transmission name="tran_right_gripper_joint">
        <type>transmission_interface/SimpleTransmission</type>
        <joint name="right_gripper_joint">
            <hardwareInterface>hardware_interface/PositionJointInterface</hardwareInterface>
        </joint>
        <actuator name="motor_right_gripper_joint">
            <hardwareInterface>hardware_interface/PositionJointInterface</hardwareInterface>
            <mechanicalReduction>1</mechanicalReduction>
        </actuator>
    </transmission>
    <gazebo>
        <plugin filename="libgazebo_ros_control.so" name="gazebo_ros_control">
            <robotNamespace>/</robotNamespace>
        </plugin>
    </gazebo>
    <transmission name="trans_front_wheel2base_link_1">
        <type>transmission_interface/SimpleTransmission</type>
        <joint name="front_wheel2base_link_1">
            <hardwareInterface>hardware_interface/EffortJointInterface</hardwareInterface>
        </joint>
        <actuator name="front_wheel2base_link_1_motor">
            <hardwareInterface>hardware_interface/EffortJointInterface</hardwareInterface>
            <mechanicalReduction>1</mechanicalReduction>
        </actuator>
    </transmission>
    <transmission name="trans_front_wheel2base_link_2">
        <type>transmission_interface/SimpleTransmission</type>
        <joint name="front_wheel2base_link_2">
            <hardwareInterface>hardware_interface/EffortJointInterface</hardwareInterface>
        </joint>
        <actuator name="front_wheel2base_link_2_motor">
            <hardwareInterface>hardware_interface/EffortJointInterface</hardwareInterface>
            <mechanicalReduction>1</mechanicalReduction>
        </actuator>
    </transmission>
    <transmission name="trans_back_wheel2base_link_1">
        <type>transmission_interface/SimpleTransmission</type>
        <joint name="back_wheel2base_link_1">
            <hardwareInterface>hardware_interface/EffortJointInterface</hardwareInterface>
        </joint>
        <actuator name="back_wheel2base_link_1_motor">
            <hardwareInterface>hardware_interface/EffortJointInterface</hardwareInterface>
            <mechanicalReduction>1</mechanicalReduction>
        </actuator>
    </transmission>
    <transmission name="trans_back_wheel2base_link_2">
        <type>transmission_interface/SimpleTransmission</type>
        <joint name="back_wheel2base_link_2">
            <hardwareInterface>hardware_interface/EffortJointInterface</hardwareInterface>
        </joint>
        <actuator name="back_wheel2base_link_2_motor">
            <hardwareInterface>hardware_interface/EffortJointInterface</hardwareInterface>
            <mechanicalReduction>1</mechanicalReduction>
        </actuator>
    </transmission>
</robot>

